Workbook

Sheet 計算シート
A1: 小児高カロリー輸液 成分計算ツール
A2: ⚠ 成分値は概算です。使用前に必ず添付文書を確認し、医師・薬剤師と連携して処方してください。
A4: ■ 患者情報
A5: 体重 (kg) | B5: 10 | C5: kg
A6: 年齢区分 | B6: 乳児(1〜12ヶ月) | C6: ↑ セルをクリックしてリストから選択
A8: ■ 目標成分量（参考値）
A9: 成分 | B9: 単位(/kg/日) | C9: 目標 最小 | D9: 目標 最大 | E9: 絶対量 最小 | F9: 絶対量 最大 | G9: 絶対単位
A10: 輸液量 | B10: mL/kg/日 | C10: =IFERROR(VLOOKUP($B$6,年齢参考値!$A:$S,2,0),"") | D10: =IFERROR(VLOOKUP($B$6,年齢参考値!$A:$S,3,0),"") | E10: =IFERROR(C10*$B$5,"") | F10: =IFERROR(D10*$B$5,"") | G10: mL/日
A11: カロリー | B11: kcal/kg/日 | C11: =IFERROR(VLOOKUP($B$6,年齢参考値!$A:$S,4,0),"") | D11: =IFERROR(VLOOKUP($B$6,年齢参考値!$A:$S,5,0),"") | E11: =IFERROR(C11*$B$5,"") | F11: =IFERROR(D11*$B$5,"") | G11: kcal/日
A12: アミノ酸 | B12: g/kg/日 | C12: =IFERROR(VLOOKUP($B$6,年齢参考値!$A:$S,6,0),"") | D12: =IFERROR(VLOOKUP($B$6,年齢参考値!$A:$S,7,0),"") | E12: =IFERROR(C12*$B$5,"") | F12: =IFERROR(D12*$B$5,"") | G12: g/日
A13: Na | B13: mEq/kg/日 | C13: =IFERROR(VLOOKUP($B$6,年齢参考値!$A:$S,8,0),"") | D13: =IFERROR(VLOOKUP($B$6,年齢参考値!$A:$S,9,0),"") | E13: =IFERROR(C13*$B$5,"") | F13: =IFERROR(D13*$B$5,"") | G13: mEq/日
A14: K | B14: mEq/kg/日 | C14: =IFERROR(VLOOKUP($B$6,年齢参考値!$A:$S,10,0),"") | D14: =IFERROR(VLOOKUP($B$6,年齢参考値!$A:$S,11,0),"") | E14: =IFERROR(C14*$B$5,"") | F14: =IFERROR(D14*$B$5,"") | G14: mEq/日
A15: Ca | B15: mEq/kg/日 | C15: =IFERROR(VLOOKUP($B$6,年齢参考値!$A:$S,12,0),"") | D15: =IFERROR(VLOOKUP($B$6,年齢参考値!$A:$S,13,0),"") | E15: =IFERROR(C15*$B$5,"") | F15: =IFERROR(D15*$B$5,"") | G15: mEq/日
A16: P | B16: mmol/kg/日 | C16: =IFERROR(VLOOKUP($B$6,年齢参考値!$A:$S,14,0),"") | D16: =IFERROR(VLOOKUP($B$6,年齢参考値!$A:$S,15,0),"") | E16: =IFERROR(C16*$B$5,"") | F16: =IFERROR(D16*$B$5,"") | G16: mmol/日
A17: Mg | B17: mEq/kg/日 | C17: =IFERROR(VLOOKUP($B$6,年齢参考値!$A:$S,16,0),"") | D17: =IFERROR(VLOOKUP($B$6,年齢参考値!$A:$S,17,0),"") | E17: =IFERROR(C17*$B$5,"") | F17: =IFERROR(D17*$B$5,"") | G17: mEq/日
A18: GIR | B18: mg/kg/min | C18: =IFERROR(VLOOKUP($B$6,年齢参考値!$A:$S,18,0),"") | D18: =IFERROR(VLOOKUP($B$6,年齢参考値!$A:$S,19,0),"") | E18: =IFERROR(VLOOKUP($B$6,年齢参考値!$A:$S,18,0),"") | F18: =IFERROR(VLOOKUP($B$6,年齢参考値!$A:$S,19,0),"") | G18: mg/kg/min
A20: ■ 製剤設定
A21: 主製剤 | B21: ハイカリックNC-N(700mL/本) | C21: ↑ リストから選択
A22: 1本の容量 (自動) | B22: =IFERROR(VLOOKUP(B21,製剤データ!$A:$J,2,0),"") | C22: mL/本（自動取得）
A23: 使用量 (mL/日) | B23: 700 | C23: mL/日 ← ここを変更
A24: （本数換算） | B24: =IFERROR(B23/B22,"") | C24: 本/日
A26: アミノ酸製剤（任意） | B26: なし | C26: グルアセト35使用時に選択
A27: アミノ酸製剤 使用量 (mL/日) | B27: 0 | C27: mL/日
A29: 5%ブドウ糖液 (mL/日) | B29: 0 | C29: mL/日
A30: 生理食塩液 (mL/日) | B30: 0 | C30: mL/日
A32: ■ 電解質補正液
A33: 10% NaCl (mL/日) | B33: 0 | C33: → Na 1.71 mEq/mL
A34: KCl 2mEq/mL (mL/日) | B34: 0 | C34: → K 2.0 mEq/mL
A35: グルコン酸Ca 10% (mL/日) | B35: 0 | C35: → Ca 0.45 mEq/mL
A36: リン酸Na液 (mL/日) | B36: 0 | C36: → P 1.0 mmol + Na 2.0 mEq/mL
A37: MgSO4 1mEq/mL (mL/日) | B37: 0 | C37: → Mg 1.0 mEq/mL
A39: ■ 計算結果
A40: 成分 | B40: 単位 | C40: 投与量/日 | D40: / kg/日 | E40: 目標 最小 | F40: 目標 最大 | G40: 判定
A41: 総輸液量 | B41: mL | C41: =B23+B27+B29+B30+B33+B34+B35+B36+B37 | D41: =IFERROR(C41/$B$5,"") | E41: =IFERROR(VLOOKUP($B$6,年齢参考値!$A:$S,2,0),"") | F41: =IFERROR(VLOOKUP($B$6,年齢参考値!$A:$S,3,0),"") | G41: =IFERROR(IF(D41="" ,"",IF(D41<E41*0.8,"不足",IF(D41>F41*1.2,"過剰",IF(D41<E41,"やや不足",IF(D41>F41,"やや過剰","適正"))))),"")
A42: 総カロリー | B42: kcal | C42: =(=IFERROR((B23/IFERROR(B22,1))*VLOOKUP(B21,製剤データ!$A:$J,3,0),0)+B29*0.05)*3.4+(=IFERROR((B23/IFERROR(B22,1))*VLOOKUP(B21,製剤データ!$A:$J,4,0),0)+IFERROR((B27/IFERROR(VLOOKUP(B26,アミノ酸製剤!$A:$E,2,0),1))*VLOOKUP(B26,アミノ酸製剤!$A:$E,3,0),0))*4.0+(=IFERROR((B23/IFERROR(B22,1))*VLOOKUP(B21,製剤データ!$A:$J,5,0),0))*9.0 | D42: =IFERROR(C42/$B$5,"") | E42: =IFERROR(VLOOKUP($B$6,年齢参考値!$A:$S,4,0),"") | F42: =IFERROR(VLOOKUP($B$6,年齢参考値!$A:$S,5,0),"") | G42: =IFERROR(IF(D42="" ,"",IF(D42<E42*0.8,"不足",IF(D42>F42*1.2,"過剰",IF(D42<E42,"やや不足",IF(D42>F42,"やや過剰","適正"))))),"")
A43: アミノ酸 | B43: g | C43: =IFERROR((B23/IFERROR(B22,1))*VLOOKUP(B21,製剤データ!$A:$J,4,0),0)+IFERROR((B27/IFERROR(VLOOKUP(B26,アミノ酸製剤!$A:$E,2,0),1))*VLOOKUP(B26,アミノ酸製剤!$A:$E,3,0),0) | D43: =IFERROR(C43/$B$5,"") | E43: =IFERROR(VLOOKUP($B$6,年齢参考値!$A:$S,6,0),"") | F43: =IFERROR(VLOOKUP($B$6,年齢参考値!$A:$S,7,0),"") | G43: =IFERROR(IF(D43="" ,"",IF(D43<E43*0.8,"不足",IF(D43>F43*1.2,"過剰",IF(D43<E43,"やや不足",IF(D43>F43,"やや過剰","適正"))))),"")
A44: 糖質 | B44: g | C44: =IFERROR((B23/IFERROR(B22,1))*VLOOKUP(B21,製剤データ!$A:$J,3,0),0)+B29*0.05 | D44: =IFERROR(C44/$B$5,"") | E44: — | F44: — | G44: （参考値なし）
A45: 脂質 | B45: g | C45: =IFERROR((B23/IFERROR(B22,1))*VLOOKUP(B21,製剤データ!$A:$J,5,0),0) | D45: =IFERROR(C45/$B$5,"") | E45: — | F45: — | G45: （参考値なし）
A46: Na | B46: mEq | C46: =IFERROR((B23/IFERROR(B22,1))*VLOOKUP(B21,製剤データ!$A:$J,6,0),0)+IFERROR((B27/IFERROR(VLOOKUP(B26,アミノ酸製剤!$A:$E,2,0),1))*VLOOKUP(B26,アミノ酸製剤!$A:$E,4,0),0)+B33*1.71+B36*2.0+B30*0.154 | D46: =IFERROR(C46/$B$5,"") | E46: =IFERROR(VLOOKUP($B$6,年齢参考値!$A:$S,8,0),"") | F46: =IFERROR(VLOOKUP($B$6,年齢参考値!$A:$S,9,0),"") | G46: =IFERROR(IF(D46="" ,"",IF(D46<E46*0.8,"不足",IF(D46>F46*1.2,"過剰",IF(D46<E46,"やや不足",IF(D46>F46,"やや過剰","適正"))))),"")
A47: K | B47: mEq | C47: =IFERROR((B23/IFERROR(B22,1))*VLOOKUP(B21,製剤データ!$A:$J,7,0),0)+IFERROR((B27/IFERROR(VLOOKUP(B26,アミノ酸製剤!$A:$E,2,0),1))*VLOOKUP(B26,アミノ酸製剤!$A:$E,5,0),0)+B34*2.0 | D47: =IFERROR(C47/$B$5,"") | E47: =IFERROR(VLOOKUP($B$6,年齢参考値!$A:$S,10,0),"") | F47: =IFERROR(VLOOKUP($B$6,年齢参考値!$A:$S,11,0),"") | G47: =IFERROR(IF(D47="" ,"",IF(D47<E47*0.8,"不足",IF(D47>F47*1.2,"過剰",IF(D47<E47,"やや不足",IF(D47>F47,"やや過剰","適正"))))),"")
...

Sheet 年齢参考値
A1: 年齢区分 | B1: 輸液min | C1: 輸液max | D1: kcalmin | E1: kcalmax | F1: AAmin | G1: AAmax | H1: Namin | I1: Namax | J1: Kmin | K1: Kmax | L1: Camin | M1: Camax | N1: Pmin | O1: Pmax | P1: Mgmin | Q1: Mgmax | R1: GIRmin | S1: GIRmax
A2: 早産児 | B2: 120 | C2: 180 | D2: 100 | E2: 120 | F2: 3 | G2: 4 | H2: 3 | I2: 5 | J2: 2 | K2: 4 | L2: 1 | M2: 3 | N2: 1.5 | O2: 2.5 | P2: 0.2 | Q2: 0.3 | R2: 4 | S2: 10
A3: 正期産新生児(0〜1ヶ月) | B3: 100 | C3: 150 | D3: 90 | E3: 110 | F3: 2.5 | G3: 3.5 | H3: 2 | I3: 4 | J3: 2 | K3: 3 | L3: 1 | M3: 2 | N3: 1 | O3: 2 | P3: 0.2 | Q3: 0.3 | R3: 4 | S3: 8
A4: 乳児(1〜12ヶ月) | B4: 100 | C4: 150 | D4: 90 | E4: 110 | F4: 2 | G4: 3 | H4: 2 | I4: 4 | J4: 2 | K4: 3 | L4: 0.5 | M4: 1.5 | N4: 0.5 | O4: 1.5 | P4: 0.2 | Q4: 0.4 | R4: 3 | S4: 8
A5: 幼児(1〜3歳) | B5: 80 | C5: 100 | D5: 75 | E5: 90 | F5: 1.5 | G5: 2.5 | H5: 2 | I5: 3 | J5: 2 | K5: 3 | L5: 0.5 | M5: 1 | N5: 0.5 | O5: 1 | P5: 0.2 | Q5: 0.4 | R5: 3 | S5: 6
A6: 学童(3〜10歳) | B6: 60 | C6: 80 | D6: 60 | E6: 75 | F6: 1 | G6: 2 | H6: 1.5 | I6: 3 | J6: 1.5 | K6: 3 | L6: 0.2 | M6: 0.5 | N6: 0.2 | O6: 0.5 | P6: 0.1 | Q6: 0.3 | R6: 2 | S6: 5
A7: 思春期(10歳以上) | B7: 50 | C7: 60 | D7: 50 | E7: 60 | F7: 0.8 | G7: 1.5 | H7: 1 | I7: 2 | J7: 1 | K7: 2 | L7: 0.2 | M7: 0.5 | N7: 0.2 | O7: 0.5 | P7: 0.1 | Q7: 0.3 | R7: 2 | S7: 4

Sheet 製剤データ
A1: 製剤名 | B1: 容量mL | C1: 糖質g | D1: AAg | E1: 脂質g | F1: Na | G1: K | H1: Ca | I1: Mg | J1: P
A2: グルアセト35(250mL/本) | B2: 250 | C2: 87.5 | D2: 0 | E2: 0 | F2: 34 | G2: 14.5 | H2: 4.5 | I2: 4 | J2: 10
A3: ハイカリックNC-N(700mL/本) | B3: 700 | C3: 175 | D3: 30 | E3: 0 | F3: 35 | G3: 20 | H3: 4.5 | I3: 5 | J3: 10
A4: ハイカリックNC-L(700mL/本) | B4: 700 | C4: 200 | D4: 30 | E4: 0 | F4: 35 | G4: 20 | H4: 4.5 | I4: 5 | J4: 10
A5: フルカリック1号(903mL/本) | B5: 903 | C5: 150 | D5: 20 | E5: 20 | F5: 35 | G5: 20 | H5: 5 | I5: 4 | J5: 10
A6: フルカリック2号(1103mL/本) | B6: 1103 | C6: 200 | D6: 40 | E6: 30 | F6: 50 | G6: 27 | H6: 7.5 | I6: 6 | J6: 15
A7: フルカリック3号(1103mL/本) | B7: 1103 | C7: 250 | D7: 60 | E7: 40 | F7: 60 | G7: 34 | H7: 10 | I7: 8 | J7: 20

Sheet アミノ酸製剤
A1: 製剤名 | B1: 容量mL | C1: AAg | D1: Na | E1: K
A2: なし | B2: 1 | C2: 0 | D2: 0 | E2: 0
A3: プレアミンP 10%(200mL/本) | B3: 200 | C3: 20 | D3: 4 | E3: 3
A4: アミパレン 10%(200mL/本) | B4: 200 | C4: 20 | D4: 0 | E4: 0
A5: モリプロンF 10%(200mL/本) | B5: 200 | C5: 20 | D5: 0 | E5: 0
